{"name": "Account creation", "status": "broken", "statusDetails": {"message": "selenium.common.exceptions.WebDriverException: Message: unknown error: Chrome failed to start: exited abnormally\n  (unknown error: DevToolsActivePort file doesn't exist)\n  (The process started from chrome location /usr/bin/google-chrome is no longer running, so ChromeDriver is assuming that Chrome has crashed.)\n\n", "trace": "  File \"/usr/local/lib/python3.7/site-packages/behave/model.py\", line 1329, in run\n    match.run(runner.context)\n  File \"/usr/local/lib/python3.7/site-packages/behave/matchers.py\", line 98, in run\n    self.func(context, *args, **kwargs)\n  File \"features/steps/steps.py\", line 17, in step_impl\n    browser.open_url(\"{}?{}\".format(BASE_URL, SIGN_IN_PATH))\n  File \"/usr/local/lib/python3.7/site-packages/selene/support/shared/browser.py\", line 140, in open_url\n    return self.open(absolute_or_relative_url)\n  File \"/usr/local/lib/python3.7/site-packages/selene/core/entity.py\", line 925, in open\n    self.driver.get(url)\n  File \"/usr/local/lib/python3.7/site-packages/selene/support/shared/browser.py\", line 56, in driver\n    webdriver: WebDriver = self.config.driver\n  File \"/usr/local/lib/python3.7/site-packages/selene/support/shared/config.py\", line 133, in driver\n    }.get(self.browser_name)()\n  File \"/usr/local/lib/python3.7/site-packages/selene/support/shared/config.py\", line 131, in <lambda>\n    options=ChromeOptions()),\n  File \"/usr/local/lib/python3.7/site-packages/selenium/webdriver/chrome/webdriver.py\", line 81, in __init__\n    desired_capabilities=desired_capabilities)\n  File \"/usr/local/lib/python3.7/site-packages/selenium/webdriver/remote/webdriver.py\", line 157, in __init__\n    self.start_session(capabilities, browser_profile)\n  File \"/usr/local/lib/python3.7/site-packages/selenium/webdriver/remote/webdriver.py\", line 252, in start_session\n    response = self.execute(Command.NEW_SESSION, parameters)\n  File \"/usr/local/lib/python3.7/site-packages/selenium/webdriver/remote/webdriver.py\", line 321, in execute\n    self.error_handler.check_response(response)\n  File \"/usr/local/lib/python3.7/site-packages/selenium/webdriver/remote/errorhandler.py\", line 242, in check_response\n    raise exception_class(message, screen, stacktrace)\n"}, "steps": [{"name": "Given I am in Sign In page", "status": "broken", "statusDetails": {"message": "selenium.common.exceptions.WebDriverException: Message: unknown error: Chrome failed to start: exited abnormally\n  (unknown error: DevToolsActivePort file doesn't exist)\n  (The process started from chrome location /usr/bin/google-chrome is no longer running, so ChromeDriver is assuming that Chrome has crashed.)\n\n", "trace": "  File \"/usr/local/lib/python3.7/site-packages/behave/model.py\", line 1329, in run\n    match.run(runner.context)\n  File \"/usr/local/lib/python3.7/site-packages/behave/matchers.py\", line 98, in run\n    self.func(context, *args, **kwargs)\n  File \"features/steps/steps.py\", line 17, in step_impl\n    browser.open_url(\"{}?{}\".format(BASE_URL, SIGN_IN_PATH))\n  File \"/usr/local/lib/python3.7/site-packages/selene/support/shared/browser.py\", line 140, in open_url\n    return self.open(absolute_or_relative_url)\n  File \"/usr/local/lib/python3.7/site-packages/selene/core/entity.py\", line 925, in open\n    self.driver.get(url)\n  File \"/usr/local/lib/python3.7/site-packages/selene/support/shared/browser.py\", line 56, in driver\n    webdriver: WebDriver = self.config.driver\n  File \"/usr/local/lib/python3.7/site-packages/selene/support/shared/config.py\", line 133, in driver\n    }.get(self.browser_name)()\n  File \"/usr/local/lib/python3.7/site-packages/selene/support/shared/config.py\", line 131, in <lambda>\n    options=ChromeOptions()),\n  File \"/usr/local/lib/python3.7/site-packages/selenium/webdriver/chrome/webdriver.py\", line 81, in __init__\n    desired_capabilities=desired_capabilities)\n  File \"/usr/local/lib/python3.7/site-packages/selenium/webdriver/remote/webdriver.py\", line 157, in __init__\n    self.start_session(capabilities, browser_profile)\n  File \"/usr/local/lib/python3.7/site-packages/selenium/webdriver/remote/webdriver.py\", line 252, in start_session\n    response = self.execute(Command.NEW_SESSION, parameters)\n  File \"/usr/local/lib/python3.7/site-packages/selenium/webdriver/remote/webdriver.py\", line 321, in execute\n    self.error_handler.check_response(response)\n  File \"/usr/local/lib/python3.7/site-packages/selenium/webdriver/remote/errorhandler.py\", line 242, in check_response\n    raise exception_class(message, screen, stacktrace)\n"}, "start": 1580741291975, "stop": 1580741294215}, {"name": "When I enter email in Create New Account section", "status": "skipped", "start": 1580741294217, "stop": 1580741294217}, {"name": "And I enter valid account details", "status": "skipped", "start": 1580741294217, "stop": 1580741294217}, {"name": "And click on Register button", "status": "skipped", "start": 1580741294217, "stop": 1580741294217}, {"name": "And My Account page is opened", "status": "skipped", "start": 1580741294217, "stop": 1580741294217}, {"name": "And I click on My Personal Information button", "status": "skipped", "start": 1580741294217, "stop": 1580741294217}, {"name": "Then Your Personal Information page is opened", "status": "skipped", "start": 1580741294217, "stop": 1580741294217}, {"name": "And correct personal information is displayed", "status": "skipped", "start": 1580741294217, "stop": 1580741294217}], "start": 1580741291975, "stop": 1580741294217, "uuid": "fcfc9594-1198-41f7-aa7b-6641b9595020", "historyId": "65deff046e9e25a740783ffb86da98a7", "labels": [{"name": "severity", "value": "normal"}, {"name": "feature", "value": "automationpractice"}, {"name": "framework", "value": "behave"}, {"name": "language", "value": "cpython3"}]}